2021-04-25 13:37:35,225 ERROR: Exception on /index [GET] [in /home/ilya-debian/PyBlog/env/lib/python3.7/site-packages/flask/app.py:1892]
Traceback (most recent call last):
  File "/home/ilya-debian/PyBlog/env/lib/python3.7/site-packages/flask/app.py", line 2447, in wsgi_app
    response = self.full_dispatch_request()
  File "/home/ilya-debian/PyBlog/env/lib/python3.7/site-packages/flask/app.py", line 1952, in full_dispatch_request
    rv = self.handle_user_exception(e)
  File "/home/ilya-debian/PyBlog/env/lib/python3.7/site-packages/flask/app.py", line 1821, in handle_user_exception
    reraise(exc_type, exc_value, tb)
  File "/home/ilya-debian/PyBlog/env/lib/python3.7/site-packages/flask/_compat.py", line 39, in reraise
    raise value
  File "/home/ilya-debian/PyBlog/env/lib/python3.7/site-packages/flask/app.py", line 1950, in full_dispatch_request
    rv = self.dispatch_request()
  File "/home/ilya-debian/PyBlog/env/lib/python3.7/site-packages/flask/app.py", line 1936, in dispatch_request
    return self.view_functions[rule.endpoint](**req.view_args)
  File "/home/ilya-debian/PyBlog/env/lib/python3.7/site-packages/flask_login/utils.py", line 272, in decorated_view
    return func(*args, **kwargs)
  File "/home/ilya-debian/PyBlog/app/routes.py", line 23, in index
    if posts.has_next else None
  File "/home/ilya-debian/PyBlog/env/lib/python3.7/site-packages/flask/helpers.py", line 370, in url_for
    return appctx.app.handle_url_build_error(error, endpoint, values)
  File "/home/ilya-debian/PyBlog/env/lib/python3.7/site-packages/flask/app.py", line 2216, in handle_url_build_error
    reraise(exc_type, exc_value, tb)
  File "/home/ilya-debian/PyBlog/env/lib/python3.7/site-packages/flask/_compat.py", line 39, in reraise
    raise value
  File "/home/ilya-debian/PyBlog/env/lib/python3.7/site-packages/flask/helpers.py", line 358, in url_for
    endpoint, values, method=method, force_external=external
  File "/home/ilya-debian/PyBlog/env/lib/python3.7/site-packages/werkzeug/routing.py", line 2179, in build
    raise BuildError(endpoint, values, method, self)
werkzeug.routing.BuildError: Could not build url for endpoint 'explore' with values ['page']. Did you mean 'edit_profile' instead?
2021-04-25 13:38:54,543 INFO: Microblog startup [in /home/ilya-debian/PyBlog/app/__init__.py:43]
2021-04-25 13:41:39,631 INFO: Microblog startup [in /home/ilya-debian/PyBlog/app/__init__.py:43]
2021-04-25 13:52:11,285 INFO: Microblog startup [in /home/ilya-debian/PyBlog/app/__init__.py:45]
2021-04-25 13:59:19,333 INFO: Microblog startup [in /home/ilya-debian/PyBlog/app/__init__.py:45]
2021-04-25 13:59:22,565 ERROR: Exception on /login [GET] [in /home/ilya-debian/PyBlog/env/lib/python3.7/site-packages/flask/app.py:1892]
Traceback (most recent call last):
  File "/home/ilya-debian/PyBlog/env/lib/python3.7/site-packages/flask/app.py", line 2447, in wsgi_app
    response = self.full_dispatch_request()
  File "/home/ilya-debian/PyBlog/env/lib/python3.7/site-packages/flask/app.py", line 1952, in full_dispatch_request
    rv = self.handle_user_exception(e)
  File "/home/ilya-debian/PyBlog/env/lib/python3.7/site-packages/flask/app.py", line 1821, in handle_user_exception
    reraise(exc_type, exc_value, tb)
  File "/home/ilya-debian/PyBlog/env/lib/python3.7/site-packages/flask/_compat.py", line 39, in reraise
    raise value
  File "/home/ilya-debian/PyBlog/env/lib/python3.7/site-packages/flask/app.py", line 1950, in full_dispatch_request
    rv = self.dispatch_request()
  File "/home/ilya-debian/PyBlog/env/lib/python3.7/site-packages/flask/app.py", line 1936, in dispatch_request
    return self.view_functions[rule.endpoint](**req.view_args)
  File "/home/ilya-debian/PyBlog/app/routes.py", line 44, in login
    return render_template('login.html', title='Sign In', form=form)
  File "/home/ilya-debian/PyBlog/env/lib/python3.7/site-packages/flask/templating.py", line 140, in render_template
    ctx.app,
  File "/home/ilya-debian/PyBlog/env/lib/python3.7/site-packages/flask/templating.py", line 120, in _render
    rv = template.render(context)
  File "/home/ilya-debian/PyBlog/env/lib/python3.7/site-packages/jinja2/environment.py", line 1090, in render
    self.environment.handle_exception()
  File "/home/ilya-debian/PyBlog/env/lib/python3.7/site-packages/jinja2/environment.py", line 832, in handle_exception
    reraise(*rewrite_traceback_stack(source=source))
  File "/home/ilya-debian/PyBlog/env/lib/python3.7/site-packages/jinja2/_compat.py", line 28, in reraise
    raise value.with_traceback(tb)
  File "/home/ilya-debian/PyBlog/app/templates/login.html", line 55, in top-level template code
    <a href="{{ url_for('reset_password_request') }}">Click to Reset It</a>
  File "/home/ilya-debian/PyBlog/env/lib/python3.7/site-packages/flask/helpers.py", line 370, in url_for
    return appctx.app.handle_url_build_error(error, endpoint, values)
  File "/home/ilya-debian/PyBlog/env/lib/python3.7/site-packages/flask/app.py", line 2216, in handle_url_build_error
    reraise(exc_type, exc_value, tb)
  File "/home/ilya-debian/PyBlog/env/lib/python3.7/site-packages/flask/_compat.py", line 39, in reraise
    raise value
  File "/home/ilya-debian/PyBlog/env/lib/python3.7/site-packages/flask/helpers.py", line 358, in url_for
    endpoint, values, method=method, force_external=external
  File "/home/ilya-debian/PyBlog/env/lib/python3.7/site-packages/werkzeug/routing.py", line 2179, in build
    raise BuildError(endpoint, values, method, self)
werkzeug.routing.BuildError: Could not build url for endpoint 'reset_password_request'. Did you mean 'edit_profile' instead?
2021-04-25 14:00:49,036 INFO: Microblog startup [in /home/ilya-debian/PyBlog/app/__init__.py:45]
2021-04-25 14:00:54,617 ERROR: Exception on /login [GET] [in /home/ilya-debian/PyBlog/env/lib/python3.7/site-packages/flask/app.py:1892]
Traceback (most recent call last):
  File "/home/ilya-debian/PyBlog/env/lib/python3.7/site-packages/flask/app.py", line 2447, in wsgi_app
    response = self.full_dispatch_request()
  File "/home/ilya-debian/PyBlog/env/lib/python3.7/site-packages/flask/app.py", line 1952, in full_dispatch_request
    rv = self.handle_user_exception(e)
  File "/home/ilya-debian/PyBlog/env/lib/python3.7/site-packages/flask/app.py", line 1821, in handle_user_exception
    reraise(exc_type, exc_value, tb)
  File "/home/ilya-debian/PyBlog/env/lib/python3.7/site-packages/flask/_compat.py", line 39, in reraise
    raise value
  File "/home/ilya-debian/PyBlog/env/lib/python3.7/site-packages/flask/app.py", line 1950, in full_dispatch_request
    rv = self.dispatch_request()
  File "/home/ilya-debian/PyBlog/env/lib/python3.7/site-packages/flask/app.py", line 1936, in dispatch_request
    return self.view_functions[rule.endpoint](**req.view_args)
  File "/home/ilya-debian/PyBlog/app/routes.py", line 44, in login
    return render_template('login.html', title='Sign In', form=form)
  File "/home/ilya-debian/PyBlog/env/lib/python3.7/site-packages/flask/templating.py", line 140, in render_template
    ctx.app,
  File "/home/ilya-debian/PyBlog/env/lib/python3.7/site-packages/flask/templating.py", line 120, in _render
    rv = template.render(context)
  File "/home/ilya-debian/PyBlog/env/lib/python3.7/site-packages/jinja2/environment.py", line 1090, in render
    self.environment.handle_exception()
  File "/home/ilya-debian/PyBlog/env/lib/python3.7/site-packages/jinja2/environment.py", line 832, in handle_exception
    reraise(*rewrite_traceback_stack(source=source))
  File "/home/ilya-debian/PyBlog/env/lib/python3.7/site-packages/jinja2/_compat.py", line 28, in reraise
    raise value.with_traceback(tb)
  File "/home/ilya-debian/PyBlog/app/templates/login.html", line 55, in top-level template code
    <!--<a href="{{ url_for('reset_password_request') }}">Click to Reset It</a>-->
  File "/home/ilya-debian/PyBlog/env/lib/python3.7/site-packages/flask/helpers.py", line 370, in url_for
    return appctx.app.handle_url_build_error(error, endpoint, values)
  File "/home/ilya-debian/PyBlog/env/lib/python3.7/site-packages/flask/app.py", line 2216, in handle_url_build_error
    reraise(exc_type, exc_value, tb)
  File "/home/ilya-debian/PyBlog/env/lib/python3.7/site-packages/flask/_compat.py", line 39, in reraise
    raise value
  File "/home/ilya-debian/PyBlog/env/lib/python3.7/site-packages/flask/helpers.py", line 358, in url_for
    endpoint, values, method=method, force_external=external
  File "/home/ilya-debian/PyBlog/env/lib/python3.7/site-packages/werkzeug/routing.py", line 2179, in build
    raise BuildError(endpoint, values, method, self)
werkzeug.routing.BuildError: Could not build url for endpoint 'reset_password_request'. Did you mean 'edit_profile' instead?
2021-04-25 14:01:17,336 INFO: Microblog startup [in /home/ilya-debian/PyBlog/app/__init__.py:45]
